<?xml version="1.0" encoding="utf-8" ?>
<!-- =================================================================================== -->
<!-- |    This document was autogenerated by xacro from /home/hp/Desktop/test_ws/src/mrm_description/urdf/mrm.xacro | -->
<!-- |    EDITING THIS FILE BY HAND IS NOT RECOMMENDED                                 | -->
<!-- =================================================================================== -->
<robot name="myrobot">
    <!--gazebo ros control-->
    <gazebo>
        <plugin filename="libgazebo_ros_control.so" name="gazebo_ros_control" />
    </gazebo>
    <!--transmissions-->
    <!--left-->
    <transmission name="ltran1">
        <type>transmission_interface/SimpleTransmission</type>
        <joint name="joint_1">
            <hardwareInterface>hardware_interface/EffortJointInterface</hardwareInterface>
        </joint>
        <actuator name="motor_1">
            <hardwareInterface>hardware_interface/EffortJointInterface</hardwareInterface>
            <mechanicalReduction>1000</mechanicalReduction>
        </actuator>
    </transmission>
    <transmission name="ltran2">
        <type>transmission_interface/SimpleTransmission</type>
        <joint name="joint_2">
            <hardwareInterface>hardware_interface/EffortJointInterface</hardwareInterface>
        </joint>
        <actuator name="motor_2">
            <hardwareInterface>hardware_interface/EffortJointInterface</hardwareInterface>
            <mechanicalReduction>1000</mechanicalReduction>
        </actuator>
    </transmission>
    <link name="robot_footprint" />
    <joint name="joint_name" type="fixed">
        <origin rpy="0.0 0.0 0.0" xyz="0.0 0.0 0.0" />
        <parent link="robot_footprint" />
        <child link="base_link" />
    </joint>
    <link name="base_link">
        
<inertial>
            <origin rpy="0.0 0.0 0.0" xyz="0.0 0.0 0.0" />
            <mass value="1024" />
            <inertia ixx="170.667" ixy="0.0" ixz="0.0" iyy="170.667" iyz="0.0" izz="170.667" />
        </inertial>

        <collision>
            <geometry>
                <box size="1 1 1" />
            </geometry>
        </collision>
        <visual name="base_link_visual">
            <origin rpy="0.0 0.0 0.0" xyz="0.0 0.0 0.0" />
            <geometry>
                <box size="1 1 1 " />
            </geometry>
        </visual>
    </link>
    <joint name="joint_1" type="revolute">
        <origin rpy="0.0 0.0 0.0" xyz="0.0 0.0 0.5" />
        <parent link="base_link" />
        <child link="link_01" />
        <axis xyz="0.0 0.0 1" />
        <limit effort="1000" lower="-3.14" upper="3.14" velocity="0.5" />
    </joint>
    <link name="link_01">
        
<inertial>
            <origin rpy="0.0 0.0 0.0" xyz="0.0 0.0 0.2" />
            <mass value="157.633" />
            <inertia ixx="13.235" ixy="0.0" ixz="0.0" iyy="13.235" iyz="0.0" izz="9.655" />
        </inertial>

        <collision>
            <geometry>
                <cylinder length="0.4" radius="0.35" />
            </geometry>
        </collision>
        <visual name="link_01_visual">
            <origin rpy="0.0 0.0 0.0" xyz="0.0 0.0 0.2" />
            <geometry>
                <cylinder length="0.4" radius="0.35" />
            </geometry>
        </visual>
    </link>
    <joint name="joint_2" type="revolute">
        <origin rpy="0.0 0.0 0.0" xyz="0.0 0.0 0.4" />
        <parent link="link_01" />
        <child link="link_02" />
        <axis xyz="0.0 1 0.0" />
        <limit effort="1000" lower="-1.57075" upper="1.57075" velocity="0.5" />
    </joint>
    <link name="link_02">
        
<inertial>
            <origin rpy="0.0 0.0 0.0" xyz="0.0 0.0 0.4" />
            <mass value="157.633" />
            <inertia ixx="13.235" ixy="0.0" ixz="0.0" iyy="13.235" iyz="0.0" izz="9.655" />
        </inertial>

        <collision>
            <geometry>
                <cylinder length="0.8" radius="0.15" />
            </geometry>
        </collision>
        <visual name="link_01_visual">
            <origin rpy="0.0 0.0 0.0" xyz="0.0 0.0 0.4" />
            <geometry>
                <cylinder length="0.8" radius="0.15" />
            </geometry>
        </visual>
    </link>
    <joint name="link_02_to_link_03" type="revolute">
        <origin rpy="0.0 0.0 0.0" xyz="0.0 0.0 0.4" />
        <parent link="link_02" />
        <child link="link_03" />
        <axis xyz="0.0 1 0.0" />
        <limit effort="1000" lower="-1.57075" upper="1.57075" velocity="0.5" />
    </joint>
    <link name="link_03">
        
<inertial>
            <origin rpy="0.0 0.0 0.0" xyz="0.0 0.0 0.8" />
            <mass value="157.633" />
            <inertia ixx="13.235" ixy="0.0" ixz="0.0" iyy="13.235" iyz="0.0" izz="9.655" />
        </inertial>

        <collision>
            <geometry>
                <cylinder length="0.8" radius="0.15" />
            </geometry>
        </collision>
        <visual name="link_01_visual">
            <origin rpy="0.0 0.0 0.0" xyz="0.0 0.0 0.8" />
            <geometry>
                <cylinder length="0.8" radius="0.15" />
            </geometry>
        </visual>
    </link>
    <joint name="link_03_to_link_04" type="revolute">
        <origin rpy="0.0 0.0 0.0" xyz="0.0 0.0 0.4" />
        <parent link="link_03" />
        <child link="link_04" />
        <axis xyz="0.0 1 0.0" />
        <limit effort="1000" lower="-1.57075" upper="1.57075" velocity="0.5" />
    </joint>
    <link name="link_04">
        
<inertial>
            <origin rpy="0.0 0.0 0.0" xyz="0.0 0.0 0.4" />
            <mass value="157.633" />
            <inertia ixx="13.235" ixy="0.0" ixz="0.0" iyy="13.235" iyz="0.0" izz="9.655" />
        </inertial>

        <collision>
            <geometry>
                <cylinder length="0.8" radius="0.15" />
            </geometry>
        </collision>
        <visual name="link_01_visual">
            <origin rpy="0.0 0.0 0.0" xyz="0.0 0.0 0.4" />
            <geometry>
                <cylinder length="0.8" radius="0.15" />
            </geometry>
        </visual>
    </link>
    <joint name="link_04_to_link_05" type="revolute">
        <origin rpy="0.0 0.0 0.0" xyz="0.0 0.0 0.4" />
        <parent link="link_04" />
        <child link="link_05" />
        <axis xyz="0.0 0.0 1" />
        <limit effort="1000" lower="-1.57075" upper="1.57075" velocity="0.5" />
    </joint>
    <link name="link_05">
        
<inertial>
            <origin rpy="0.0 0.0 0.0" xyz="0.0 0.0 0.4" />
            <mass value="157.633" />
            <inertia ixx="13.235" ixy="0.0" ixz="0.0" iyy="13.235" iyz="0.0" izz="9.655" />
        </inertial>

        <collision>
            <geometry>
                <cylinder length="0.8" radius="0.15" />
            </geometry>
        </collision>
        <visual name="link_01_visual">
            <origin rpy="0.0 0.0 0.0" xyz="0.0 0.0 0.4" />
            <geometry>
                <cylinder length="0.8" radius="0.15" />
            </geometry>
        </visual>
    </link>
    <transmission name="trans_joint_1">
        <type>transmission_interface/SimpleTransmission</type>
        <joint name="joint_1">
            <hardwareInterface>hardware_interface/EffortJointInterface</hardwareInterface>
        </joint>
        <actuator name="joint_1_motor">
            <hardwareInterface>hardware_interface/EffortJointInterface</hardwareInterface>
            <mechanicalReduction>1</mechanicalReduction>
        </actuator>
    </transmission>
    <transmission name="trans_joint_2">
        <type>transmission_interface/SimpleTransmission</type>
        <joint name="joint_2">
            <hardwareInterface>hardware_interface/EffortJointInterface</hardwareInterface>
        </joint>
        <actuator name="joint_2_motor">
            <hardwareInterface>hardware_interface/EffortJointInterface</hardwareInterface>
            <mechanicalReduction>1</mechanicalReduction>
        </actuator>
    </transmission>
    <transmission name="trans_link_02_to_link_03">
        <type>transmission_interface/SimpleTransmission</type>
        <joint name="link_02_to_link_03">
            <hardwareInterface>hardware_interface/EffortJointInterface</hardwareInterface>
        </joint>
        <actuator name="link_02_to_link_03_motor">
            <hardwareInterface>hardware_interface/EffortJointInterface</hardwareInterface>
            <mechanicalReduction>1</mechanicalReduction>
        </actuator>
    </transmission>
    <transmission name="trans_link_03_to_link_04">
        <type>transmission_interface/SimpleTransmission</type>
        <joint name="link_03_to_link_04">
            <hardwareInterface>hardware_interface/EffortJointInterface</hardwareInterface>
        </joint>
        <actuator name="link_03_to_link_04_motor">
            <hardwareInterface>hardware_interface/EffortJointInterface</hardwareInterface>
            <mechanicalReduction>1</mechanicalReduction>
        </actuator>
    </transmission>
    <transmission name="trans_link_04_to_link_05">
        <type>transmission_interface/SimpleTransmission</type>
        <joint name="link_04_to_link_05">
            <hardwareInterface>hardware_interface/EffortJointInterface</hardwareInterface>
        </joint>
        <actuator name="link_04_to_link_05_motor">
            <hardwareInterface>hardware_interface/EffortJointInterface</hardwareInterface>
            <mechanicalReduction>1</mechanicalReduction>
        </actuator>
    </transmission>
    <gazebo>
        <plugin name="gazebo_ros_control" filename="libgazebo_ros_control.so">
            <robotNamespace>/</robotNamespace>
        </plugin>
    </gazebo>
</robot>

<transmission name="ltran1">
        <type>transmission_interface/SimpleTransmission</type>
        <joint name="joint_1">
            <hardwareInterface>hardware_interface/EffortJointInterface</hardwareInterface>
        </joint>
        <actuator name="motor_1">
            <hardwareInterface>hardware_interface/EffortJointInterface</hardwareInterface>
            <mechanicalReduction>1000</mechanicalReduction>
        </actuator>
    </transmission>
    <transmission name="ltran2">
        <type>transmission_interface/SimpleTransmission</type>
        <joint name="joint_2">
            <hardwareInterface>hardware_interface/EffortJointInterface</hardwareInterface>
        </joint>
        <actuator name="motor_2">
            <hardwareInterface>hardware_interface/EffortJointInterface</hardwareInterface>
            <mechanicalReduction>1000</mechanicalReduction>
        </actuator>
    </transmission>
    <link name="robot_footprint" />
    <joint name="joint_name" type="fixed">
        <origin rpy="0.0 0.0 0.0" xyz="0.0 0.0 0.0" />
        <parent link="robot_footprint" />
        <child link="base_link" />
    </joint>
    <link name="base_link">
        <inertial>
            <origin rpy="0.0 0.0 0.0" xyz="0.0 0.0 0.0" />
            <mass value="1024" />
            <inertia ixx="170.667" ixy="0.0" ixz="0.0" iyy="170.667" iyz="0.0" izz="170.667" />
        </inertial>
        <collision>
            <geometry>
                <box size="1 1 1" />
            </geometry>
        </collision>
        <visual name="base_link_visual">
            <origin rpy="0.0 0.0 0.0" xyz="0.0 0.0 0.0" />
            <geometry>
                <box size="1 1 1 " />
            </geometry>
        </visual>
    </link>
    <joint name="joint_1" type="revolute">
        <origin rpy="0.0 0.0 0.0" xyz="0.0 0.0 0.5" />
        <parent link="base_link" />
        <child link="link_01" />
        <axis xyz="0.0 0.0 1" />
        <limit effort="1000" lower="-3.14" upper="3.14" velocity="0.5" />
    </joint>
    <link name="link_01">
        <inertial>
            <origin rpy="0.0 0.0 0.0" xyz="0.0 0.0 0.2" />
            <mass value="157.633" />
            <inertia ixx="13.235" ixy="0.0" ixz="0.0" iyy="13.235" iyz="0.0" izz="9.655" />
        </inertial>
        <collision>
            <geometry>
                <cylinder length="0.4" radius="0.35" />
            </geometry>
        </collision>
        <visual name="link_01_visual">
            <origin rpy="0.0 0.0 0.0" xyz="0.0 0.0 0.2" />
            <geometry>
                <cylinder length="0.4" radius="0.35" />
            </geometry>
        </visual>
    </link>
    <joint name="joint_2" type="revolute">
        <origin rpy="0.0 0.0 0.0" xyz="0.0 0.0 0.4" />
        <parent link="link_01" />
        <child link="link_02" />
        <axis xyz="0.0 1 0.0" />
        <limit effort="1000" lower="-1.57075" upper="1.57075" velocity="0.5" />
    </joint>
    <link name="link_02">
        <inertial>
            <origin rpy="0.0 0.0 0.0" xyz="0.0 0.0 0.4" />
            <mass value="157.633" />
            <inertia ixx="13.235" ixy="0.0" ixz="0.0" iyy="13.235" iyz="0.0" izz="9.655" />
        </inertial>
        <collision>
            <geometry>
                <cylinder length="0.8" radius="0.15" />
            </geometry>
        </collision>
        <visual name="link_01_visual">
            <origin rpy="0.0 0.0 0.0" xyz="0.0 0.0 0.4" />
            <geometry>
                <cylinder length="0.8" radius="0.15" />
            </geometry>
        </visual>
    </link>
    <joint name="link_02_to_link_03" type="revolute">
        <origin rpy="0.0 0.0 0.0" xyz="0.0 0.0 0.4" />
        <parent link="link_02" />
        <child link="link_03" />
        <axis xyz="0.0 1 0.0" />
        <limit effort="1000" lower="-1.57075" upper="1.57075" velocity="0.5" />
    </joint>
    <link name="link_03">
        <inertial>
            <origin rpy="0.0 0.0 0.0" xyz="0.0 0.0 0.8" />
            <mass value="157.633" />
            <inertia ixx="13.235" ixy="0.0" ixz="0.0" iyy="13.235" iyz="0.0" izz="9.655" />
        </inertial>
        <collision>
            <geometry>
                <cylinder length="0.8" radius="0.15" />
            </geometry>
        </collision>
        <visual name="link_01_visual">
            <origin rpy="0.0 0.0 0.0" xyz="0.0 0.0 0.8" />
            <geometry>
                <cylinder length="0.8" radius="0.15" />
            </geometry>
        </visual>
    </link>
    <joint name="link_03_to_link_04" type="revolute">
        <origin rpy="0.0 0.0 0.0" xyz="0.0 0.0 0.4" />
        <parent link="link_03" />
        <child link="link_04" />
        <axis xyz="0.0 1 0.0" />
        <limit effort="1000" lower="-1.57075" upper="1.57075" velocity="0.5" />
    </joint>
    <link name="link_04">
        <inertial>
            <origin rpy="0.0 0.0 0.0" xyz="0.0 0.0 0.4" />
            <mass value="157.633" />
            <inertia ixx="13.235" ixy="0.0" ixz="0.0" iyy="13.235" iyz="0.0" izz="9.655" />
        </inertial>
        <collision>
            <geometry>
                <cylinder length="0.8" radius="0.15" />
            </geometry>
        </collision>
        <visual name="link_01_visual">
            <origin rpy="0.0 0.0 0.0" xyz="0.0 0.0 0.4" />
            <geometry>
                <cylinder length="0.8" radius="0.15" />
            </geometry>
        </visual>
    </link>
    <joint name="link_04_to_link_05" type="revolute">
        <origin rpy="0.0 0.0 0.0" xyz="0.0 0.0 0.4" />
        <parent link="link_04" />
        <child link="link_05" />
        <axis xyz="0.0 0.0 1" />
        <limit effort="1000" lower="-1.57075" upper="1.57075" velocity="0.5" />
    </joint>
    <link name="link_05">
        <inertial>
            <origin rpy="0.0 0.0 0.0" xyz="0.0 0.0 0.4" />
            <mass value="157.633" />
            <inertia ixx="13.235" ixy="0.0" ixz="0.0" iyy="13.235" iyz="0.0" izz="9.655" />
        </inertial>
        <collision>
            <geometry>
                <cylinder length="0.8" radius="0.15" />
            </geometry>
        </collision>
        <visual name="link_01_visual">
            <origin rpy="0.0 0.0 0.0" xyz="0.0 0.0 0.4" />
            <geometry>
                <cylinder length="0.8" radius="0.15" />
            </geometry>
        </visual>
    </link>
    <transmission name="trans_joint_1">
        <type>transmission_interface/SimpleTransmission</type>
        <joint name="joint_1">
            <hardwareInterface>hardware_interface/EffortJointInterface</hardwareInterface>
        </joint>
        <actuator name="joint_1_motor">
            <hardwareInterface>hardware_interface/EffortJointInterface</hardwareInterface>
            <mechanicalReduction>1</mechanicalReduction>
        </actuator>
    </transmission>
    <transmission name="trans_joint_2">
        <type>transmission_interface/SimpleTransmission</type>
        <joint name="joint_2">
            <hardwareInterface>hardware_interface/EffortJointInterface</hardwareInterface>
        </joint>
        <actuator name="joint_2_motor">
            <hardwareInterface>hardware_interface/EffortJointInterface</hardwareInterface>
            <mechanicalReduction>1</mechanicalReduction>
        </actuator>
    </transmission>
    <transmission name="trans_link_02_to_link_03">
        <type>transmission_interface/SimpleTransmission</type>
        <joint name="link_02_to_link_03">
            <hardwareInterface>hardware_interface/EffortJointInterface</hardwareInterface>
        </joint>
        <actuator name="link_02_to_link_03_motor">
            <hardwareInterface>hardware_interface/EffortJointInterface</hardwareInterface>
            <mechanicalReduction>1</mechanicalReduction>
        </actuator>
    </transmission>
    <transmission name="trans_link_03_to_link_04">
        <type>transmission_interface/SimpleTransmission</type>
        <joint name="link_03_to_link_04">
            <hardwareInterface>hardware_interface/EffortJointInterface</hardwareInterface>
        </joint>
        <actuator name="link_03_to_link_04_motor">
            <hardwareInterface>hardware_interface/EffortJointInterface</hardwareInterface>
            <mechanicalReduction>1</mechanicalReduction>
        </actuator>
    </transmission>
    <transmission name="trans_link_04_to_link_05">
        <type>transmission_interface/SimpleTransmission</type>
        <joint name="link_04_to_link_05">
            <hardwareInterface>hardware_interface/EffortJointInterface</hardwareInterface>
        </joint>
        <actuator name="link_04_to_link_05_motor">
            <hardwareInterface>hardware_interface/EffortJointInterface</hardwareInterface>
            <mechanicalReduction>1</mechanicalReduction>
        </actuator>
    </transmission>
    <gazebo>
        <plugin name="gazebo_ros_control" filename="libgazebo_ros_control.so">
            <robotNamespace>/</robotNamespace>
        </plugin>
    </gazebo>
</robot>
